Workbook

Sheet Depositos
C1: =IF(SUM(C6:C206)>0,"❌","✔️") -> ✔️ | D1: =IF(SUM(D6:D206)>0,"❌","✔️") -> ✔️ | E1: =IF(SUM(E6:E206)>0,"❌","✔️") -> ✔️ | F1: =IF(SUM(F6:F206)>0,"❌","✔️") -> ✔️ | I1: =IF(COUNTIFS(I6:I206,">0")=0,"❌","✔️") -> ✔️ | J1: =IF('Cheques'!H1>1,"❌","✔️") -> ✔️
I2: CIF del Cliente:
I3: Depositos | S3: Resumen por moneda
T4: NIO | U4: USD | V4: EUR
I5: No. deposito | J5: No. bolsa | K5: No. Cuenta | L5: Moneda | M5: Cheques Locales BAC | N5: Cheques Locales Otros | O5: Efectivo | P5: Total | Q5: Referencia | S5: Efectivo | T5: =SUMIF(L6:L206,"="&T4,O6:O206) -> 1000 | U5: =SUMIF(L6:L206,"="&U4,O6:O206) -> 400 | V5: =SUMIF(L6:L206,"="&V4,O6:O206) -> 0
C6: =IF(AND(I6<>"",ISBLANK(J6)),1,0) -> 0 | D6: =IF(AND(I6<>"",ISBLANK(K6)),1,0) -> 0 | E6: =IF(AND(I6<>"",ISBLANK(L6)),1,0) -> 0 | F6: =IF(AND(I6<>"",P6<=0),1,0) -> 0 | H6: =SUM(C6:G6) -> 0 | I6: =IF(7-(COUNTBLANK(J6:O6) + COUNTBLANK(Q6))>0,1,"") -> 1 | P6: =SUM(M6:O6) -> 200 | S6: Cheques | T6: =SUMIF(L6:L206,"="&T4,M6:M206) + SUMIF(L6:L206,"="&T4,N6:N206) -> 0 | U6: =SUMIF(L6:L206,"="&U4,M6:M206)+SUMIF(L6:L206,"="&U4,N6:N206) -> 200 | V6: =SUMIF(L6:L206,"="&V4,M6:M206)+SUMIF(L6:L206,"="&V4,N6:N206) -> 0
C7: =IF(AND(I7<>"",ISBLANK(J7)),1,0) -> 0 | D7: =IF(AND(I7<>"",ISBLANK(K7)),1,0) -> 0 | E7: =IF(AND(I7<>"",ISBLANK(L7)),1,0) -> 0 | F7: =IF(AND(I7<>"",P7<=0),1,0) -> 0 | H7: =SUM(C7:G7) -> 0 | I7: =IFERROR(IF(7-(COUNTBLANK(J7:O7) + COUNTBLANK(Q7))>0,MAX($I$6:I6)+1,""),"") -> 2 | P7: =SUM(M7:O7) -> 400 | T7: =SUM(T5:T6) -> 1000 | U7: =SUM(U5:U6) -> 600 | V7: =SUM(V5:V6) -> 0
C8: =IF(AND(I8<>"",ISBLANK(J8)),1,0) -> 0 | D8: =IF(AND(I8<>"",ISBLANK(K8)),1,0) -> 0 | E8: =IF(AND(I8<>"",ISBLANK(L8)),1,0) -> 0 | F8: =IF(AND(I8<>"",P8<=0),1,0) -> 0 | H8: =SUM(C8:G8) -> 0 | I8: =IFERROR(IF(7-(COUNTBLANK(J8:O8) + COUNTBLANK(Q8))>0,MAX($I$6:I7)+1,""),"") -> 3 | P8: =SUM(M8:O8) -> 500
C9: =IF(AND(I9<>"",ISBLANK(J9)),1,0) -> 0 | D9: =IF(AND(I9<>"",ISBLANK(K9)),1,0) -> 0 | E9: =IF(AND(I9<>"",ISBLANK(L9)),1,0) -> 0 | F9: =IF(AND(I9<>"",P9<=0),1,0) -> 0 | H9: =SUM(C9:G9) -> 0 | I9: =IFERROR(IF(7-(COUNTBLANK(J9:O9) + COUNTBLANK(Q9))>0,MAX($I$6:I8)+1,""),"") -> 4 | P9: =SUM(M9:O9) -> 500
C10: =IF(AND(I10<>"",ISBLANK(J10)),1,0) -> 0 | D10: =IF(AND(I10<>"",ISBLANK(K10)),1,0) -> 0 | E10: =IF(AND(I10<>"",ISBLANK(L10)),1,0) -> 0 | F10: =IF(AND(I10<>"",P10<=0),1,0) -> 0 | H10: =SUM(C10:G10) -> 0 | I10: =IFERROR(IF(7-(COUNTBLANK(J10:O10) + COUNTBLANK(Q10))>0,MAX($I$6:I9)+1,""),"") | P10: =SUM(M10:O10) -> 0 | S10: Depositos vs Cheques Declarados | V10: =IF(OR(T14<>0,U14<>0,V14<>0),"❌","✔️") -> ✔️
C11: =IF(AND(I11<>"",ISBLANK(J11)),1,0) -> 0 | D11: =IF(AND(I11<>"",ISBLANK(K11)),1,0) -> 0 | E11: =IF(AND(I11<>"",ISBLANK(L11)),1,0) -> 0 | F11: =IF(AND(I11<>"",P11<=0),1,0) -> 0 | H11: =SUM(C11:G11) -> 0 | I11: =IFERROR(IF(7-(COUNTBLANK(J11:O11) + COUNTBLANK(Q11))>0,MAX($I$6:I10)+1,""),"") | P11: =SUM(M11:O11) -> 0 | T11: NIO | U11: USD | V11: EUR
C12: =IF(AND(I12<>"",ISBLANK(J12)),1,0) -> 0 | D12: =IF(AND(I12<>"",ISBLANK(K12)),1,0) -> 0 | E12: =IF(AND(I12<>"",ISBLANK(L12)),1,0) -> 0 | F12: =IF(AND(I12<>"",P12<=0),1,0) -> 0 | H12: =SUM(C12:G12) -> 0 | I12: =IFERROR(IF(7-(COUNTBLANK(J12:O12) + COUNTBLANK(Q12))>0,MAX($I$6:I11)+1,""),"") | P12: =SUM(M12:O12) -> 0 | S12: Depositos | T12: =SUMIF($L$6:$L$206,"="&T11,$M$6:$M$206)+SUMIF($L$6:$L$206,"="&T11,$N$6:$N$206) -> 0 | U12: =SUMIF($L$6:$L$206,"="&U11,$M$6:$M$206)+SUMIF($L$6:$L$206,"="&U11,$N$6:$N$206) -> 200 | V12: =SUMIF($L$6:$L$206,"="&V11,$M$6:$M$206)+SUMIF($L$6:$L$206,"="&V11,$N$6:$N$206) -> 0
C13: =IF(AND(I13<>"",ISBLANK(J13)),1,0) -> 0 | D13: =IF(AND(I13<>"",ISBLANK(K13)),1,0) -> 0 | E13: =IF(AND(I13<>"",ISBLANK(L13)),1,0) -> 0 | F13: =IF(AND(I13<>"",P13<=0),1,0) -> 0 | H13: =SUM(C13:G13) -> 0 | I13: =IFERROR(IF(7-(COUNTBLANK(J13:O13) + COUNTBLANK(Q13))>0,MAX($I$6:I12)+1,""),"") | P13: =SUM(M13:O13) -> 0 | S13: Cheques declarados | T13: =SUMIFS('Cheques'!$E$2:$E$51,'Cheques'!$F$2:$F$51,"=0",'Cheques'!$D$2:$D$51,"="&Depositos!T11) -> 0 | U13: =SUMIFS('Cheques'!$E$2:$E$51,'Cheques'!$F$2:$F$51,"=0",'Cheques'!$D$2:$D$51,"="&Depositos!U11) -> 200 | V13: =SUMIFS('Cheques'!$E$2:$E$51,'Cheques'!$F$2:$F$51,"=0",'Cheques'!$D$2:$D$51,"="&Depositos!V11) -> 0
C14: =IF(AND(I14<>"",ISBLANK(J14)),1,0) -> 0 | D14: =IF(AND(I14<>"",ISBLANK(K14)),1,0) -> 0 | E14: =IF(AND(I14<>"",ISBLANK(L14)),1,0) -> 0 | F14: =IF(AND(I14<>"",P14<=0),1,0) -> 0 | H14: =SUM(C14:G14) -> 0 | I14: =IFERROR(IF(7-(COUNTBLANK(J14:O14) + COUNTBLANK(Q14))>0,MAX($I$6:I13)+1,""),"") | P14: =SUM(M14:O14) -> 0 | S14: Diferencia | T14: =T12-T13 -> 0 | U14: =U12-U13 -> 0 | V14: =V12-V13 -> 0
C15: =IF(AND(I15<>"",ISBLANK(J15)),1,0) -> 0 | D15: =IF(AND(I15<>"",ISBLANK(K15)),1,0) -> 0 | E15: =IF(AND(I15<>"",ISBLANK(L15)),1,0) -> 0 | F15: =IF(AND(I15<>"",P15<=0),1,0) -> 0 | H15: =SUM(C15:G15) -> 0 | I15: =IFERROR(IF(7-(COUNTBLANK(J15:O15) + COUNTBLANK(Q15))>0,MAX($I$6:I14)+1,""),"") | P15: =SUM(M15:O15) -> 0
C16: =IF(AND(I16<>"",ISBLANK(J16)),1,0) -> 0 | D16: =IF(AND(I16<>"",ISBLANK(K16)),1,0) -> 0 | E16: =IF(AND(I16<>"",ISBLANK(L16)),1,0) -> 0 | F16: =IF(AND(I16<>"",P16<=0),1,0) -> 0 | H16: =SUM(C16:G16) -> 0 | I16: =IFERROR(IF(7-(COUNTBLANK(J16:O16) + COUNTBLANK(Q16))>0,MAX($I$6:I15)+1,""),"") | P16: =SUM(M16:O16) -> 0
C17: =IF(AND(I17<>"",ISBLANK(J17)),1,0) -> 0 | D17: =IF(AND(I17<>"",ISBLANK(K17)),1,0) -> 0 | E17: =IF(AND(I17<>"",ISBLANK(L17)),1,0) -> 0 | F17: =IF(AND(I17<>"",P17<=0),1,0) -> 0 | H17: =SUM(C17:G17) -> 0 | I17: =IFERROR(IF(7-(COUNTBLANK(J17:O17) + COUNTBLANK(Q17))>0,MAX($I$6:I16)+1,""),"") | P17: =SUM(M17:O17) -> 0 | S17: Resumen por cuenta
C18: =IF(AND(I18<>"",ISBLANK(J18)),1,0) -> 0 | D18: =IF(AND(I18<>"",ISBLANK(K18)),1,0) -> 0 | E18: =IF(AND(I18<>"",ISBLANK(L18)),1,0) -> 0 | F18: =IF(AND(I18<>"",P18<=0),1,0) -> 0 | H18: =SUM(C18:G18) -> 0 | I18: =IFERROR(IF(7-(COUNTBLANK(J18:O18) + COUNTBLANK(Q18))>0,MAX($I$6:I17)+1,""),"") | P18: =SUM(M18:O18) -> 0 | T18: NIO | U18: USD | V18: EUR | W18: =IF(SUM(W19:W38)>0,"❌","✔️") -> ✔️
C19: =IF(AND(I19<>"",ISBLANK(J19)),1,0) -> 0 | D19: =IF(AND(I19<>"",ISBLANK(K19)),1,0) -> 0 | E19: =IF(AND(I19<>"",ISBLANK(L19)),1,0) -> 0 | F19: =IF(AND(I19<>"",P19<=0),1,0) -> 0 | H19: =SUM(C19:G19) -> 0 | I19: =IFERROR(IF(7-(COUNTBLANK(J19:O19) + COUNTBLANK(Q19))>0,MAX($I$6:I18)+1,""),"") | P19: =SUM(M19:O19) -> 0 | S19: {=_xlfn.UNIQUE(_xlfn._xlws.FILTER(K6:K206,K6:K206<>""))} -> 366789987 | T19: =SUMIFS($P$6:$P$206,$L$6:$L$206,"="&T$18,$K$6:$K$206,"="&$S19,$K$6:$K$206,"<>"&"") -> 0 | U19: =SUMIFS($P$6:$P$206,$L$6:$L$206,"="&U$18,$K$6:$K$206,"="&$S19,$K$6:$K$206,"<>"&"") -> 600 | V19: =SUMIFS($P$6:$P$206,$L$6:$L$206,"="&V$18,$K$6:$K$206,"="&$S19,$K$6:$K$206,"<>"&"") -> 0 | W19: =IF(COUNTIF(T19:V19,">0")>1,1,0) -> 0
C20: =IF(AND(I20<>"",ISBLANK(J20)),1,0) -> 0 | D20: =IF(AND(I20<>"",ISBLANK(K20)),1,0) -> 0 | E20: =IF(AND(I20<>"",ISBLANK(L20)),1,0) -> 0 | F20: =IF(AND(I20<>"",P20<=0),1,0) -> 0 | H20: =SUM(C20:G20) -> 0 | I20: =IFERROR(IF(7-(COUNTBLANK(J20:O20) + COUNTBLANK(Q20))>0,MAX($I$6:I19)+1,""),"") | P20: =SUM(M20:O20) -> 0 | S20: 366789988 | T20: =SUMIFS($P$6:$P$206,$L$6:$L$206,"="&T$18,$K$6:$K$206,"="&$S20,$K$6:$K$206,"<>"&"") -> 1000 | U20: =SUMIFS($P$6:$P$206,$L$6:$L$206,"="&U$18,$K$6:$K$206,"="&$S20,$K$6:$K$206,"<>"&"") -> 0 | V20: =SUMIFS($P$6:$P$206,$L$6:$L$206,"="&V$18,$K$6:$K$206,"="&$S20,$K$6:$K$206,"<>"&"") -> 0 | W20: =IF(COUNTIF(T20:V20,">0")>1,1,0) -> 0
C21: =IF(AND(I21<>"",ISBLANK(J21)),1,0) -> 0 | D21: =IF(AND(I21<>"",ISBLANK(K21)),1,0) -> 0 | E21: =IF(AND(I21<>"",ISBLANK(L21)),1,0) -> 0 | F21: =IF(AND(I21<>"",P21<=0),1,0) -> 0 | H21: =SUM(C21:G21) -> 0 | I21: =IFERROR(IF(7-(COUNTBLANK(J21:O21) + COUNTBLANK(Q21))>0,MAX($I$6:I20)+1,""),"") | P21: =SUM(M21:O21) -> 0 | T21: =SUMIFS($P$6:$P$206,$L$6:$L$206,"="&T$18,$K$6:$K$206,"="&$S21,$K$6:$K$206,"<>"&"") -> 0 | U21: =SUMIFS($P$6:$P$206,$L$6:$L$206,"="&U$18,$K$6:$K$206,"="&$S21,$K$6:$K$206,"<>"&"") -> 0 | V21: =SUMIFS($P$6:$P$206,$L$6:$L$206,"="&V$18,$K$6:$K$206,"="&$S21,$K$6:$K$206,"<>"&"") -> 0 | W21: =IF(COUNTIF(T21:V21,">0")>1,1,0) -> 0
C22: =IF(AND(I22<>"",ISBLANK(J22)),1,0) -> 0 | D22: =IF(AND(I22<>"",ISBLANK(K22)),1,0) -> 0 | E22: =IF(AND(I22<>"",ISBLANK(L22)),1,0) -> 0 | F22: =IF(AND(I22<>"",P22<=0),1,0) -> 0 | H22: =SUM(C22:G22) -> 0 | I22: =IFERROR(IF(7-(COUNTBLANK(J22:O22) + COUNTBLANK(Q22))>0,MAX($I$6:I21)+1,""),"") | P22: =SUM(M22:O22) -> 0 | T22: =SUMIFS($P$6:$P$206,$L$6:$L$206,"="&T$18,$K$6:$K$206,"="&$S22,$K$6:$K$206,"<>"&"") -> 0 | U22: =SUMIFS($P$6:$P$206,$L$6:$L$206,"="&U$18,$K$6:$K$206,"="&$S22,$K$6:$K$206,"<>"&"") -> 0 | V22: =SUMIFS($P$6:$P$206,$L$6:$L$206,"="&V$18,$K$6:$K$206,"="&$S22,$K$6:$K$206,"<>"&"") -> 0 | W22: =IF(COUNTIF(T22:V22,">0")>1,1,0) -> 0
C23: =IF(AND(I23<>"",ISBLANK(J23)),1,0) -> 0 | D23: =IF(AND(I23<>"",ISBLANK(K23)),1,0) -> 0 | E23: =IF(AND(I23<>"",ISBLANK(L23)),1,0) -> 0 | F23: =IF(AND(I23<>"",P23<=0),1,0) -> 0 | H23: =SUM(C23:G23) -> 0 | I23: =IFERROR(IF(7-(COUNTBLANK(J23:O23) + COUNTBLANK(Q23))>0,MAX($I$6:I22)+1,""),"") | P23: =SUM(M23:O23) -> 0 | T23: =SUMIFS($P$6:$P$206,$L$6:$L$206,"="&T$18,$K$6:$K$206,"="&$S23,$K$6:$K$206,"<>"&"") -> 0 | U23: =SUMIFS($P$6:$P$206,$L$6:$L$206,"="&U$18,$K$6:$K$206,"="&$S23,$K$6:$K$206,"<>"&"") -> 0 | V23: =SUMIFS($P$6:$P$206,$L$6:$L$206,"="&V$18,$K$6:$K$206,"="&$S23,$K$6:$K$206,"<>"&"") -> 0 | W23: =IF(COUNTIF(T23:V23,">0")>1,1,0) -> 0
C24: =IF(AND(I24<>"",ISBLANK(J24)),1,0) -> 0 | D24: =IF(AND(I24<>"",ISBLANK(K24)),1,0) -> 0 | E24: =IF(AND(I24<>"",ISBLANK(L24)),1,0) -> 0 | F24: =IF(AND(I24<>"",P24<=0),1,0) -> 0 | H24: =SUM(C24:G24) -> 0 | I24: =IFERROR(IF(7-(COUNTBLANK(J24:O24) + COUNTBLANK(Q24))>0,MAX($I$6:I23)+1,""),"") | P24: =SUM(M24:O24) -> 0 | T24: =SUMIFS($P$6:$P$206,$L$6:$L$206,"="&T$18,$K$6:$K$206,"="&$S24,$K$6:$K$206,"<>"&"") -> 0 | U24: =SUMIFS($P$6:$P$206,$L$6:$L$206,"="&U$18,$K$6:$K$206,"="&$S24,$K$6:$K$206,"<>"&"") -> 0 | V24: =SUMIFS($P$6:$P$206,$L$6:$L$206,"="&V$18,$K$6:$K$206,"="&$S24,$K$6:$K$206,"<>"&"") -> 0 | W24: =IF(COUNTIF(T24:V24,">0")>1,1,0) -> 0
C25: =IF(AND(I25<>"",ISBLANK(J25)),1,0) -> 0 | D25: =IF(AND(I25<>"",ISBLANK(K25)),1,0) -> 0 | E25: =IF(AND(I25<>"",ISBLANK(L25)),1,0) -> 0 | F25: =IF(AND(I25<>"",P25<=0),1,0) -> 0 | H25: =SUM(C25:G25) -> 0 | I25: =IFERROR(IF(7-(COUNTBLANK(J25:O25) + COUNTBLANK(Q25))>0,MAX($I$6:I24)+1,""),"") | P25: =SUM(M25:O25) -> 0 | T25: =SUMIFS($P$6:$P$206,$L$6:$L$206,"="&T$18,$K$6:$K$206,"="&$S25,$K$6:$K$206,"<>"&"") -> 0 | U25: =SUMIFS($P$6:$P$206,$L$6:$L$206,"="&U$18,$K$6:$K$206,"="&$S25,$K$6:$K$206,"<>"&"") -> 0 | V25: =SUMIFS($P$6:$P$206,$L$6:$L$206,"="&V$18,$K$6:$K$206,"="&$S25,$K$6:$K$206,"<>"&"") -> 0 | W25: =IF(COUNTIF(T25:V25,">0")>1,1,0) -> 0
C26: =IF(AND(I26<>"",ISBLANK(J26)),1,0) -> 0 | D26: =IF(AND(I26<>"",ISBLANK(K26)),1,0) -> 0 | E26: =IF(AND(I26<>"",ISBLANK(L26)),1,0) -> 0 | F26: =IF(AND(I26<>"",P26<=0),1,0) -> 0 | H26: =SUM(C26:G26) -> 0 | I26: =IFERROR(IF(7-(COUNTBLANK(J26:O26) + COUNTBLANK(Q26))>0,MAX($I$6:I25)+1,""),"") | P26: =SUM(M26:O26) -> 0 | T26: =SUMIFS($P$6:$P$206,$L$6:$L$206,"="&T$18,$K$6:$K$206,"="&$S26,$K$6:$K$206,"<>"&"") -> 0 | U26: =SUMIFS($P$6:$P$206,$L$6:$L$206,"="&U$18,$K$6:$K$206,"="&$S26,$K$6:$K$206,"<>"&"") -> 0 | V26: =SUMIFS($P$6:$P$206,$L$6:$L$206,"="&V$18,$K$6:$K$206,"="&$S26,$K$6:$K$206,"<>"&"") -> 0 | W26: =IF(COUNTIF(T26:V26,">0")>1,1,0) -> 0
C27: =IF(AND(I27<>"",ISBLANK(J27)),1,0) -> 0 | D27: =IF(AND(I27<>"",ISBLANK(K27)),1,0) -> 0 | E27: =IF(AND(I27<>"",ISBLANK(L27)),1,0) -> 0 | F27: =IF(AND(I27<>"",P27<=0),1,0) -> 0 | H27: =SUM(C27:G27) -> 0 | I27: =IFERROR(IF(7-(COUNTBLANK(J27:O27) + COUNTBLANK(Q27))>0,MAX($I$6:I26)+1,""),"") | P27: =SUM(M27:O27) -> 0 | T27: =SUMIFS($P$6:$P$206,$L$6:$L$206,"="&T$18,$K$6:$K$206,"="&$S27,$K$6:$K$206,"<>"&"") -> 0 | U27: =SUMIFS($P$6:$P$206,$L$6:$L$206,"="&U$18,$K$6:$K$206,"="&$S27,$K$6:$K$206,"<>"&"") -> 0 | V27: =SUMIFS($P$6:$P$206,$L$6:$L$206,"="&V$18,$K$6:$K$206,"="&$S27,$K$6:$K$206,"<>"&"") -> 0 | W27: =IF(COUNTIF(T27:V27,">0")>1,1,0) -> 0
C28: =IF(AND(I28<>"",ISBLANK(J28)),1,0) -> 0 | D28: =IF(AND(I28<>"",ISBLANK(K28)),1,0) -> 0 | E28: =IF(AND(I28<>"",ISBLANK(L28)),1,0) -> 0 | F28: =IF(AND(I28<>"",P28<=0),1,0) -> 0 | H28: =SUM(C28:G28) -> 0 | I28: =IFERROR(IF(7-(COUNTBLANK(J28:O28) + COUNTBLANK(Q28))>0,MAX($I$6:I27)+1,""),"") | P28: =SUM(M28:O28) -> 0 | T28: =SUMIFS($P$6:$P$206,$L$6:$L$206,"="&T$18,$K$6:$K$206,"="&$S28,$K$6:$K$206,"<>"&"") -> 0 | U28: =SUMIFS($P$6:$P$206,$L$6:$L$206,"="&U$18,$K$6:$K$206,"="&$S28,$K$6:$K$206,"<>"&"") -> 0 | V28: =SUMIFS($P$6:$P$206,$L$6:$L$206,"="&V$18,$K$6:$K$206,"="&$S28,$K$6:$K$206,"<>"&"") -> 0 | W28: =IF(COUNTIF(T28:V28,">0")>1,1,0) -> 0
C29: =IF(AND(I29<>"",ISBLANK(J29)),1,0) -> 0 | D29: =IF(AND(I29<>"",ISBLANK(K29)),1,0) -> 0 | E29: =IF(AND(I29<>"",ISBLANK(L29)),1,0) -> 0 | F29: =IF(AND(I29<>"",P29<=0),1,0) -> 0 | H29: =SUM(C29:G29) -> 0 | I29: =IFERROR(IF(7-(COUNTBLANK(J29:O29) + COUNTBLANK(Q29))>0,MAX($I$6:I28)+1,""),"") | P29: =SUM(M29:O29) -> 0 | T29: =SUMIFS($P$6:$P$206,$L$6:$L$206,"="&T$18,$K$6:$K$206,"="&$S29,$K$6:$K$206,"<>"&"") -> 0 | U29: =SUMIFS($P$6:$P$206,$L$6:$L$206,"="&U$18,$K$6:$K$206,"="&$S29,$K$6:$K$206,"<>"&"") -> 0 | V29: =SUMIFS($P$6:$P$206,$L$6:$L$206,"="&V$18,$K$6:$K$206,"="&$S29,$K$6:$K$206,"<>"&"") -> 0 | W29: =IF(COUNTIF(T29:V29,">0")>1,1,0) -> 0
C30: =IF(AND(I30<>"",ISBLANK(J30)),1,0) -> 0 | D30: =IF(AND(I30<>"",ISBLANK(K30)),1,0) -> 0 | E30: =IF(AND(I30<>"",ISBLANK(L30)),1,0) -> 0 | F30: =IF(AND(I30<>"",P30<=0),1,0) -> 0 | H30: =SUM(C30:G30) -> 0 | I30: =IFERROR(IF(7-(COUNTBLANK(J30:O30) + COUNTBLANK(Q30))>0,MAX($I$6:I29)+1,""),"") | P30: =SUM(M30:O30) -> 0 | T30: =SUMIFS($P$6:$P$206,$L$6:$L$206,"="&T$18,$K$6:$K$206,"="&$S30,$K$6:$K$206,"<>"&"") -> 0 | U30: =SUMIFS($P$6:$P$206,$L$6:$L$206,"="&U$18,$K$6:$K$206,"="&$S30,$K$6:$K$206,"<>"&"") -> 0 | V30: =SUMIFS($P$6:$P$206,$L$6:$L$206,"="&V$18,$K$6:$K$206,"="&$S30,$K$6:$K$206,"<>"&"") -> 0 | W30: =IF(COUNTIF(T30:V30,">0")>1,1,0) -> 0
C31: =IF(AND(I31<>"",ISBLANK(J31)),1,0) -> 0 | D31: =IF(AND(I31<>"",ISBLANK(K31)),1,0) -> 0 | E31: =IF(AND(I31<>"",ISBLANK(L31)),1,0) -> 0 | F31: =IF(AND(I31<>"",P31<=0),1,0) -> 0 | H31: =SUM(C31:G31) -> 0 | I31: =IFERROR(IF(7-(COUNTBLANK(J31:O31) + COUNTBLANK(Q31))>0,MAX($I$6:I30)+1,""),"") | P31: =SUM(M31:O31) -> 0 | T31: =SUMIFS($P$6:$P$206,$L$6:$L$206,"="&T$18,$K$6:$K$206,"="&$S31,$K$6:$K$206,"<>"&"") -> 0 | U31: =SUMIFS($P$6:$P$206,$L$6:$L$206,"="&U$18,$K$6:$K$206,"="&$S31,$K$6:$K$206,"<>"&"") -> 0 | V31: =SUMIFS($P$6:$P$206,$L$6:$L$206,"="&V$18,$K$6:$K$206,"="&$S31,$K$6:$K$206,"<>"&"") -> 0 | W31: =IF(COUNTIF(T31:V31,">0")>1,1,0) -> 0
C32: =IF(AND(I32<>"",ISBLANK(J32)),1,0) -> 0 | D32: =IF(AND(I32<>"",ISBLANK(K32)),1,0) -> 0 | E32: =IF(AND(I32<>"",ISBLANK(L32)),1,0) -> 0 | F32: =IF(AND(I32<>"",P32<=0),1,0) -> 0 | H32: =SUM(C32:G32) -> 0 | I32: =IFERROR(IF(7-(COUNTBLANK(J32:O32) + COUNTBLANK(Q32))>0,MAX($I$6:I31)+1,""),"") | P32: =SUM(M32:O32) -> 0 | T32: =SUMIFS($P$6:$P$206,$L$6:$L$206,"="&T$18,$K$6:$K$206,"="&$S32,$K$6:$K$206,"<>"&"") -> 0 | U32: =SUMIFS($P$6:$P$206,$L$6:$L$206,"="&U$18,$K$6:$K$206,"="&$S32,$K$6:$K$206,"<>"&"") -> 0 | V32: =SUMIFS($P$6:$P$206,$L$6:$L$206,"="&V$18,$K$6:$K$206,"="&$S32,$K$6:$K$206,"<>"&"") -> 0 | W32: =IF(COUNTIF(T32:V32,">0")>1,1,0) -> 0
... C38: =IF(AND(I38<>"",ISBLANK(J38)),1,0) -> 0 | D38: =IF(AND(I38<>"",ISBLANK(K38)),1,0) -> 0 | E38: =IF(AND(I38<>"",ISBLANK(L38)),1,0) -> 0 | F38: =IF(AND(I38<>"",P38<=0),1,0) -> 0 | H38: =SUM(C38:G38) -> 0 | I38: =IFERROR(IF(7-(COUNTBLANK(J38:O38) + COUNTBLANK(Q38))>0,MAX($I$6:I37)+1,""),"") | P38: =SUM(M38:O38) -> 0 | T38: =SUMIFS($P$6:$P$206,$L$6:$L$206,"="&T$18,$K$6:$K$206,"="&$S38,$K$6:$K$206,"<>"&"") -> 0 | U38: =SUMIFS($P$6:$P$206,$L$6:$L$206,"="&U$18,$K$6:$K$206,"="&$S38,$K$6:$K$206,"<>"&"") -> 0 | V38: =SUMIFS($P$6:$P$206,$L$6:$L$206,"="&V$18,$K$6:$K$206,"="&$S38,$K$6:$K$206,"<>"&"") -> 0 | W38: =IF(COUNTIF(T38:V38,">0")>1,1,0) -> 0
C39: =IF(AND(I39<>"",ISBLANK(J39)),1,0) -> 0 | D39: =IF(AND(I39<>"",ISBLANK(K39)),1,0) -> 0 | E39: =IF(AND(I39<>"",ISBLANK(L39)),1,0) -> 0 | F39: =IF(AND(I39<>"",P39<=0),1,0) -> 0 | H39: =SUM(C39:G39) -> 0 | I39: =IFERROR(IF(7-(COUNTBLANK(J39:O39) + COUNTBLANK(Q39))>0,MAX($I$6:I38)+1,""),"") | P39: =SUM(M39:O39) -> 0
C40: =IF(AND(I40<>"",ISBLANK(J40)),1,0) -> 0 | D40: =IF(AND(I40<>"",ISBLANK(K40)),1,0) -> 0 | E40: =IF(AND(I40<>"",ISBLANK(L40)),1,0) -> 0 | F40: =IF(AND(I40<>"",P40<=0),1,0) -> 0 | H40: =SUM(C40:G40) -> 0 | I40: =IFERROR(IF(7-(COUNTBLANK(J40:O40) + COUNTBLANK(Q40))>0,MAX($I$6:I39)+1,""),"") | P40: =SUM(M40:O40) -> 0 | S40: Resumen por bolsa
C41: =IF(AND(I41<>"",ISBLANK(J41)),1,0) -> 0 | D41: =IF(AND(I41<>"",ISBLANK(K41)),1,0) -> 0 | E41: =IF(AND(I41<>"",ISBLANK(L41)),1,0) -> 0 | F41: =IF(AND(I41<>"",P41<=0),1,0) -> 0 | H41: =SUM(C41:G41) -> 0 | I41: =IFERROR(IF(7-(COUNTBLANK(J41:O41) + COUNTBLANK(Q41))>0,MAX($I$6:I40)+1,""),"") | P41: =SUM(M41:O41) -> 0 | T41: NIO | U41: USD | V41: EUR
C42: =IF(AND(I42<>"",ISBLANK(J42)),1,0) -> 0 | D42: =IF(AND(I42<>"",ISBLANK(K42)),1,0) -> 0 | E42: =IF(AND(I42<>"",ISBLANK(L42)),1,0) -> 0 | F42: =IF(AND(I42<>"",P42<=0),1,0) -> 0 | H42: =SUM(C42:G42) -> 0 | I42: =IFERROR(IF(7-(COUNTBLANK(J42:O42) + COUNTBLANK(Q42))>0,MAX($I$6:I41)+1,""),"") | P42: =SUM(M42:O42) -> 0 | S42: {=_xlfn.UNIQUE(_xlfn._xlws.FILTER(J6:J206,J6:J206<>""))} -> 123456789 | T42: =SUMIFS($P$6:$P$206,$L$6:$L$206,"="&T$41,$J$6:$J$206,"="&$S42) -> 1000 | U42: =SUMIFS($P$6:$P$206,$L$6:$L$206,"="&U$41,$J$6:$J$206,"="&$S42) -> 600 | V42: =SUMIFS($P$6:$P$206,$L$6:$L$206,"="&V$41,$J$6:$J$206,"="&$S42) -> 0
C43: =IF(AND(I43<>"",ISBLANK(J43)),1,0) -> 0 | D43: =IF(AND(I43<>"",ISBLANK(K43)),1,0) -> 0 | E43: =IF(AND(I43<>"",ISBLANK(L43)),1,0) -> 0 | F43: =IF(AND(I43<>"",P43<=0),1,0) -> 0 | H43: =SUM(C43:G43) -> 0 | I43: =IFERROR(IF(7-(COUNTBLANK(J43:O43) + COUNTBLANK(Q43))>0,MAX($I$6:I42)+1,""),"") | P43: =SUM(M43:O43) -> 0 | T43: =SUMIFS($P$6:$P$206,$L$6:$L$206,"="&T$41,$J$6:$J$206,"="&$S43) -> 0 | U43: =SUMIFS($P$6:$P$206,$L$6:$L$206,"="&U$41,$J$6:$J$206,"="&$S43) -> 0 | V43: =SUMIFS($P$6:$P$206,$L$6:$L$206,"="&V$41,$J$6:$J$206,"="&$S43) -> 0
C44: =IF(AND(I44<>"",ISBLANK(J44)),1,0) -> 0 | D44: =IF(AND(I44<>"",ISBLANK(K44)),1,0) -> 0 | E44: =IF(AND(I44<>"",ISBLANK(L44)),1,0) -> 0 | F44: =IF(AND(I44<>"",P44<=0),1,0) -> 0 | H44: =SUM(C44:G44) -> 0 | I44: =IFERROR(IF(7-(COUNTBLANK(J44:O44) + COUNTBLANK(Q44))>0,MAX($I$6:I43)+1,""),"") | P44: =SUM(M44:O44) -> 0 | T44: =SUMIFS($P$6:$P$206,$L$6:$L$206,"="&T$41,$J$6:$J$206,"="&$S44) -> 0 | U44: =SUMIFS($P$6:$P$206,$L$6:$L$206,"="&U$41,$J$6:$J$206,"="&$S44) -> 0 | V44: =SUMIFS($P$6:$P$206,$L$6:$L$206,"="&V$41,$J$6:$J$206,"="&$S44) -> 0
C45: =IF(AND(I45<>"",ISBLANK(J45)),1,0) -> 0 | D45: =IF(AND(I45<>"",ISBLANK(K45)),1,0) -> 0 | E45: =IF(AND(I45<>"",ISBLANK(L45)),1,0) -> 0 | F45: =IF(AND(I45<>"",P45<=0),1,0) -> 0 | H45: =SUM(C45:G45) -> 0 | I45: =IFERROR(IF(7-(COUNTBLANK(J45:O45) + COUNTBLANK(Q45))>0,MAX($I$6:I44)+1,""),"") | P45: =SUM(M45:O45) -> 0 | T45: =SUMIFS($P$6:$P$206,$L$6:$L$206,"="&T$41,$J$6:$J$206,"="&$S45) -> 0 | U45: =SUMIFS($P$6:$P$206,$L$6:$L$206,"="&U$41,$J$6:$J$206,"="&$S45) -> 0 | V45: =SUMIFS($P$6:$P$206,$L$6:$L$206,"="&V$41,$J$6:$J$206,"="&$S45) -> 0
...

Sheet Cheques
A1: No. Deposito | B1: No. Cheque | C1: Tipo | D1: Moneda | E1: Monto | F1: =IF(MAX(F2:F51)>0,"❌","✔️") -> ✔️ | H1: =MAX(H2:H51) -> 1
F2: =IF(AND(COUNTBLANK(A2:E2)<>5,COUNTBLANK(A2:E2)<>0),1,0) -> 0 | G2: =IF(F2>0,0,E2) -> 200 | H2: =COUNTIFS($B$2:$B$51,"<>"&"",$B$2:$B$51,"="&B2) -> 1
F3: =IF(AND(COUNTBLANK(A3:E3)<>5,COUNTBLANK(A3:E3)<>0),1,0) -> 0 | H3: =COUNTIFS($B$2:$B$51,"<>"&"",$B$2:$B$51,"="&B3) -> 0
F4: =IF(AND(COUNTBLANK(A4:E4)<>5,COUNTBLANK(A4:E4)<>0),1,0) -> 0 | H4: =COUNTIFS($B$2:$B$51,"<>"&"",$B$2:$B$51,"="&B4) -> 0
F5: =IF(AND(COUNTBLANK(A5:E5)<>5,COUNTBLANK(A5:E5)<>0),1,0) -> 0 | H5: =COUNTIFS($B$2:$B$51,"<>"&"",$B$2:$B$51,"="&B5) -> 0
F6: =IF(AND(COUNTBLANK(A6:E6)<>5,COUNTBLANK(A6:E6)<>0),1,0) -> 0 | H6: =COUNTIFS($B$2:$B$51,"<>"&"",$B$2:$B$51,"="&B6) -> 0
F7: =IF(AND(COUNTBLANK(A7:E7)<>5,COUNTBLANK(A7:E7)<>0),1,0) -> 0 | H7: =COUNTIFS($B$2:$B$51,"<>"&"",$B$2:$B$51,"="&B7) -> 0
F8: =IF(AND(COUNTBLANK(A8:E8)<>5,COUNTBLANK(A8:E8)<>0),1,0) -> 0 | H8: =COUNTIFS($B$2:$B$51,"<>"&"",$B$2:$B$51,"="&B8) -> 0
F9: =IF(AND(COUNTBLANK(A9:E9)<>5,COUNTBLANK(A9:E9)<>0),1,0) -> 0 | H9: =COUNTIFS($B$2:$B$51,"<>"&"",$B$2:$B$51,"="&B9) -> 0
F10: =IF(AND(COUNTBLANK(A10:E10)<>5,COUNTBLANK(A10:E10)<>0),1,0) -> 0 | H10: =COUNTIFS($B$2:$B$51,"<>"&"",$B$2:$B$51,"="&B10) -> 0
F11: =IF(AND(COUNTBLANK(A11:E11)<>5,COUNTBLANK(A11:E11)<>0),1,0) -> 0 | H11: =COUNTIFS($B$2:$B$51,"<>"&"",$B$2:$B$51,"="&B11) -> 0
F12: =IF(AND(COUNTBLANK(A12:E12)<>5,COUNTBLANK(A12:E12)<>0),1,0) -> 0 | H12: =COUNTIFS($B$2:$B$51,"<>"&"",$B$2:$B$51,"="&B12) -> 0
F13: =IF(AND(COUNTBLANK(A13:E13)<>5,COUNTBLANK(A13:E13)<>0),1,0) -> 0 | H13: =COUNTIFS($B$2:$B$51,"<>"&"",$B$2:$B$51,"="&B13) -> 0
F14: =IF(AND(COUNTBLANK(A14:E14)<>5,COUNTBLANK(A14:E14)<>0),1,0) -> 0 | H14: =COUNTIFS($B$2:$B$51,"<>"&"",$B$2:$B$51,"="&B14) -> 0
... F51: =IF(AND(COUNTBLANK(A51:E51)<>5,COUNTBLANK(A51:E51)<>0),1,0) -> 0 | H51: =COUNTIFS($B$2:$B$51,"<>"&"",$B$2:$B$51,"="&B51) -> 0

Sheet Metadata
A1: TemplateId | B1: CH-TPL-Depositos
A2: TemplateVersion | B2: 1.1.1
A3: ClientCIF | B3: =Depositos!J2
